Traceback (most recent call last):
  File "/usr/share/miniconda3/envs/main-conda-env/lib/python3.8/site-packages/jupyter_cache/executors/utils.py", line 51, in single_nb_execution
    executenb(
  File "/usr/share/miniconda3/envs/main-conda-env/lib/python3.8/site-packages/nbclient/client.py", line 1204, in execute
    return NotebookClient(nb=nb, resources=resources, km=km, **kwargs).execute()
  File "/usr/share/miniconda3/envs/main-conda-env/lib/python3.8/site-packages/nbclient/util.py", line 84, in wrapped
    return just_run(coro(*args, **kwargs))
  File "/usr/share/miniconda3/envs/main-conda-env/lib/python3.8/site-packages/nbclient/util.py", line 62, in just_run
    return loop.run_until_complete(coro)
  File "/usr/share/miniconda3/envs/main-conda-env/lib/python3.8/asyncio/base_events.py", line 616, in run_until_complete
    return future.result()
  File "/usr/share/miniconda3/envs/main-conda-env/lib/python3.8/site-packages/nbclient/client.py", line 663, in async_execute
    await self.async_execute_cell(
  File "/usr/share/miniconda3/envs/main-conda-env/lib/python3.8/site-packages/nbclient/client.py", line 965, in async_execute_cell
    await self._check_raise_for_error(cell, cell_index, exec_reply)
  File "/usr/share/miniconda3/envs/main-conda-env/lib/python3.8/site-packages/nbclient/client.py", line 862, in _check_raise_for_error
    raise CellExecutionError.from_cell_and_msg(cell, exec_reply_content)
nbclient.exceptions.CellExecutionError: An error occurred while executing the following cell:
------------------
import pandas as pd
import matplotlib.pyplot as plt

# Used to build the decision tree and evaluate it
from sklearn import tree
from sklearn.model_selection import train_test_split
from sklearn.metrics import classification_report, confusion_matrix, accuracy_score
import sklearn.metrics as metrics

# Used to graph the decision tree
import graphviz
from sklearn.tree import export_graphviz
from IPython.display import Image
------------------

[0;31m---------------------------------------------------------------------------[0m
[0;31mModuleNotFoundError[0m                       Traceback (most recent call last)
Cell [0;32mIn [1], line 11[0m
[1;32m      8[0m [38;5;28;01mimport[39;00m [38;5;21;01msklearn[39;00m[38;5;21;01m.[39;00m[38;5;21;01mmetrics[39;00m [38;5;28;01mas[39;00m [38;5;21;01mmetrics[39;00m
[1;32m     10[0m [38;5;66;03m# Used to graph the decision tree[39;00m
[0;32m---> 11[0m [38;5;28;01mimport[39;00m [38;5;21;01mgraphviz[39;00m
[1;32m     12[0m [38;5;28;01mfrom[39;00m [38;5;21;01msklearn[39;00m[38;5;21;01m.[39;00m[38;5;21;01mtree[39;00m [38;5;28;01mimport[39;00m export_graphviz
[1;32m     13[0m [38;5;28;01mfrom[39;00m [38;5;21;01mIPython[39;00m[38;5;21;01m.[39;00m[38;5;21;01mdisplay[39;00m [38;5;28;01mimport[39;00m Image

[0;31mModuleNotFoundError[0m: No module named 'graphviz'
ModuleNotFoundError: No module named 'graphviz'

