Traceback (most recent call last):
  File "/usr/share/miniconda3/envs/main-conda-env/lib/python3.8/site-packages/jupyter_cache/executors/utils.py", line 51, in single_nb_execution
    executenb(
  File "/usr/share/miniconda3/envs/main-conda-env/lib/python3.8/site-packages/nbclient/client.py", line 1093, in execute
    return NotebookClient(nb=nb, resources=resources, km=km, **kwargs).execute()
  File "/usr/share/miniconda3/envs/main-conda-env/lib/python3.8/site-packages/nbclient/util.py", line 84, in wrapped
    return just_run(coro(*args, **kwargs))
  File "/usr/share/miniconda3/envs/main-conda-env/lib/python3.8/site-packages/nbclient/util.py", line 62, in just_run
    return loop.run_until_complete(coro)
  File "/usr/share/miniconda3/envs/main-conda-env/lib/python3.8/asyncio/base_events.py", line 616, in run_until_complete
    return future.result()
  File "/usr/share/miniconda3/envs/main-conda-env/lib/python3.8/site-packages/nbclient/client.py", line 559, in async_execute
    await self.async_execute_cell(
  File "/usr/share/miniconda3/envs/main-conda-env/lib/python3.8/site-packages/nbclient/client.py", line 854, in async_execute_cell
    self._check_raise_for_error(cell, exec_reply)
  File "/usr/share/miniconda3/envs/main-conda-env/lib/python3.8/site-packages/nbclient/client.py", line 756, in _check_raise_for_error
    raise CellExecutionError.from_cell_and_msg(cell, exec_reply_content)
nbclient.exceptions.CellExecutionError: An error occurred while executing the following cell:
------------------
# Packages for data management and mathematical operations.
import pandas as pd
import numpy as np

# Package for plotting.
import matplotlib.pyplot as plt

# Scikit-learn libraries to perform clustering and evaluation.
from sklearn.cluster import KMeans
from sklearn.preprocessing import StandardScaler
from sklearn.metrics import confusion_matrix, f1_score

# Package used in the confusion matrix function.
import itertools
------------------

[0;31m---------------------------------------------------------------------------[0m
[0;31mModuleNotFoundError[0m                       Traceback (most recent call last)
[0;32m/tmp/ipykernel_3332/3251690887.py[0m in [0;36m<module>[0;34m[0m
[1;32m      7[0m [0;34m[0m[0m
[1;32m      8[0m [0;31m# Scikit-learn libraries to perform clustering and evaluation.[0m[0;34m[0m[0;34m[0m[0;34m[0m[0m
[0;32m----> 9[0;31m [0;32mfrom[0m [0msklearn[0m[0;34m.[0m[0mcluster[0m [0;32mimport[0m [0mKMeans[0m[0;34m[0m[0;34m[0m[0m
[0m[1;32m     10[0m [0;32mfrom[0m [0msklearn[0m[0;34m.[0m[0mpreprocessing[0m [0;32mimport[0m [0mStandardScaler[0m[0;34m[0m[0;34m[0m[0m
[1;32m     11[0m [0;32mfrom[0m [0msklearn[0m[0;34m.[0m[0mmetrics[0m [0;32mimport[0m [0mconfusion_matrix[0m[0;34m,[0m [0mf1_score[0m[0;34m[0m[0;34m[0m[0m

[0;31mModuleNotFoundError[0m: No module named 'sklearn'
ModuleNotFoundError: No module named 'sklearn'

