Traceback (most recent call last):
  File "/usr/share/miniconda3/envs/main-conda-env/lib/python3.8/site-packages/jupyter_cache/executors/utils.py", line 51, in single_nb_execution
    executenb(
  File "/usr/share/miniconda3/envs/main-conda-env/lib/python3.8/site-packages/nbclient/client.py", line 1204, in execute
    return NotebookClient(nb=nb, resources=resources, km=km, **kwargs).execute()
  File "/usr/share/miniconda3/envs/main-conda-env/lib/python3.8/site-packages/nbclient/util.py", line 84, in wrapped
    return just_run(coro(*args, **kwargs))
  File "/usr/share/miniconda3/envs/main-conda-env/lib/python3.8/site-packages/nbclient/util.py", line 62, in just_run
    return loop.run_until_complete(coro)
  File "/usr/share/miniconda3/envs/main-conda-env/lib/python3.8/asyncio/base_events.py", line 616, in run_until_complete
    return future.result()
  File "/usr/share/miniconda3/envs/main-conda-env/lib/python3.8/site-packages/nbclient/client.py", line 663, in async_execute
    await self.async_execute_cell(
  File "/usr/share/miniconda3/envs/main-conda-env/lib/python3.8/site-packages/nbclient/client.py", line 965, in async_execute_cell
    await self._check_raise_for_error(cell, cell_index, exec_reply)
  File "/usr/share/miniconda3/envs/main-conda-env/lib/python3.8/site-packages/nbclient/client.py", line 862, in _check_raise_for_error
    raise CellExecutionError.from_cell_and_msg(cell, exec_reply_content)
nbclient.exceptions.CellExecutionError: An error occurred while executing the following cell:
------------------
import os
import sys
import zipfile


def csv_files(source_dir):
    for filename in os.listdir(source_dir):
        if filename.endswith('.csv'):
            yield filename


source_dir = '~/Downloads/drive-download-20211120T082520Z-001' 
dest_dir = '~/Downloads/drive-download-20211120T082520Z-001'

os.chdir(dest_dir)  # To work around zipfile limitations

for csv_filename in csv_files(source_dir):
    file_root = os.path.splitext(csv_filename)[0]
    zip_file_name = file_root + '.zip'
    zip_file_path = os.path.join(dest_dir, zip_file_name)
    with zipfile.ZipFile(zip_file_path, 'w', zipfile.ZIP_DEFLATED) as zf:
        zf.write(csv_filename)

------------------

[0;31m---------------------------------------------------------------------------[0m
[0;31mFileNotFoundError[0m                         Traceback (most recent call last)
Cell [0;32mIn [1], line 15[0m
[1;32m     12[0m source_dir [38;5;241m=[39m [38;5;124m'[39m[38;5;124m~/Downloads/drive-download-20211120T082520Z-001[39m[38;5;124m'[39m 
[1;32m     13[0m dest_dir [38;5;241m=[39m [38;5;124m'[39m[38;5;124m~/Downloads/drive-download-20211120T082520Z-001[39m[38;5;124m'[39m
[0;32m---> 15[0m os[38;5;241m.[39mchdir(dest_dir)  [38;5;66;03m# To work around zipfile limitations[39;00m
[1;32m     17[0m [38;5;28;01mfor[39;00m csv_filename [38;5;129;01min[39;00m csv_files(source_dir):
[1;32m     18[0m     file_root [38;5;241m=[39m os[38;5;241m.[39mpath[38;5;241m.[39msplitext(csv_filename)[[38;5;241m0[39m]

[0;31mFileNotFoundError[0m: [Errno 2] No such file or directory: '~/Downloads/drive-download-20211120T082520Z-001'
FileNotFoundError: [Errno 2] No such file or directory: '~/Downloads/drive-download-20211120T082520Z-001'

