Traceback (most recent call last):
  File "/usr/share/miniconda3/envs/main-conda-env/lib/python3.8/site-packages/jupyter_cache/executors/utils.py", line 51, in single_nb_execution
    executenb(
  File "/usr/share/miniconda3/envs/main-conda-env/lib/python3.8/site-packages/nbclient/client.py", line 1093, in execute
    return NotebookClient(nb=nb, resources=resources, km=km, **kwargs).execute()
  File "/usr/share/miniconda3/envs/main-conda-env/lib/python3.8/site-packages/nbclient/util.py", line 84, in wrapped
    return just_run(coro(*args, **kwargs))
  File "/usr/share/miniconda3/envs/main-conda-env/lib/python3.8/site-packages/nbclient/util.py", line 62, in just_run
    return loop.run_until_complete(coro)
  File "/usr/share/miniconda3/envs/main-conda-env/lib/python3.8/asyncio/base_events.py", line 616, in run_until_complete
    return future.result()
  File "/usr/share/miniconda3/envs/main-conda-env/lib/python3.8/site-packages/nbclient/client.py", line 559, in async_execute
    await self.async_execute_cell(
  File "/usr/share/miniconda3/envs/main-conda-env/lib/python3.8/site-packages/nbclient/client.py", line 854, in async_execute_cell
    self._check_raise_for_error(cell, exec_reply)
  File "/usr/share/miniconda3/envs/main-conda-env/lib/python3.8/site-packages/nbclient/client.py", line 756, in _check_raise_for_error
    raise CellExecutionError.from_cell_and_msg(cell, exec_reply_content)
nbclient.exceptions.CellExecutionError: An error occurred while executing the following cell:
------------------
import os
import sys
import zipfile


def csv_files(source_dir):
    for filename in os.listdir(source_dir):
        if filename.endswith('.csv'):
            yield filename


source_dir = '~/Downloads/drive-download-20211120T082520Z-001' 
dest_dir = '~/Downloads/drive-download-20211120T082520Z-001'

os.chdir(dest_dir)  # To work around zipfile limitations

for csv_filename in csv_files(source_dir):
    file_root = os.path.splitext(csv_filename)[0]
    zip_file_name = file_root + '.zip'
    zip_file_path = os.path.join(dest_dir, zip_file_name)
    with zipfile.ZipFile(zip_file_path, 'w', zipfile.ZIP_DEFLATED) as zf:
        zf.write(csv_filename)

------------------

[0;31m---------------------------------------------------------------------------[0m
[0;31mFileNotFoundError[0m                         Traceback (most recent call last)
[0;32m/tmp/ipykernel_3084/2622171480.py[0m in [0;36m<module>[0;34m[0m
[1;32m     13[0m [0mdest_dir[0m [0;34m=[0m [0;34m'~/Downloads/drive-download-20211120T082520Z-001'[0m[0;34m[0m[0;34m[0m[0m
[1;32m     14[0m [0;34m[0m[0m
[0;32m---> 15[0;31m [0mos[0m[0;34m.[0m[0mchdir[0m[0;34m([0m[0mdest_dir[0m[0;34m)[0m  [0;31m# To work around zipfile limitations[0m[0;34m[0m[0;34m[0m[0m
[0m[1;32m     16[0m [0;34m[0m[0m
[1;32m     17[0m [0;32mfor[0m [0mcsv_filename[0m [0;32min[0m [0mcsv_files[0m[0;34m([0m[0msource_dir[0m[0;34m)[0m[0;34m:[0m[0;34m[0m[0;34m[0m[0m

[0;31mFileNotFoundError[0m: [Errno 2] No such file or directory: '~/Downloads/drive-download-20211120T082520Z-001'
FileNotFoundError: [Errno 2] No such file or directory: '~/Downloads/drive-download-20211120T082520Z-001'

